<?xml version="1.0" ?>
<!-- 
  This is not a standalone urdf for kobuki. It simply defines the 'kobuki' tag that can
  be incorporated by other urdf files (e.g. turtlebot).
  
  See kobuki_standalone.urdf.xacro for a standalone urdf to be tested with
      kobuki_description/launch/view_model.launch
 -->
<robot name="kobuki" xmlns:xacro="http://ros.org/wiki/xacro">
  <include filename="$(find kobuki_description)/urdf/common_properties.urdf.xacro"/>
  <include filename="$(find kobuki_description)/urdf/kobuki_gazebo.urdf.xacro"/>

  <!-- Xacro properties -->
  <xacro:property name="M_SCALE" value="0.001"/>

  <!-- Kobuki --> 
  <xacro:macro name="kobuki">   
    <link name="base_footprint">
      <visual>
        <origin xyz="0 0 0" rpy="0 0 0"/>
        <geometry>
          <box size="0.001 0.001 0.001"/>
        </geometry>
        <xacro:insert_block name="material_black" />
      </visual>
      <collision>
        <origin xyz="0 0 0.035" rpy="0 0 0"/>
        <geometry>
         <box size="0.001 0.001 0.001"/>
        </geometry>
      </collision>
    </link>
     <!--
       Base link is set at the bottom of the base mould.
       This is done to be compatible with the way base link
       was configured for turtlebot 1. Refer to
       
       https://github.com/turtlebot/turtlebot/issues/40
       
       To put the base link at the more oft used wheel
       axis, set the z-distance from the base_footprint
       to 0.352.
      -->
    <joint name="base_joint" type="fixed">
      <origin xyz="0 0 0.0102" rpy="0 0 0" />        
      <parent link="base_footprint"/>
      <child link="base_link" />
    </joint>
    <link name="base_link">
      <visual>
        <geometry>
          <mesh filename="package://kobuki_description/meshes/base.dae" scale="${M_SCALE} ${M_SCALE} ${M_SCALE}"/>
        </geometry>
        <origin xyz="0.0 0 0.05469" rpy="${M_PI/2} 0 ${M_PI/2}"/>
        <xacro:insert_block name="material_black"/>
      </visual>
      <collision>
        <geometry>
          <cylinder length="0.10938" radius="0.175615"/>
        </geometry>
        <origin xyz="0.0 0.0 0.05469" rpy="0 0 0"/>
      </collision>
      <inertial>
        <mass value="2.4"/> <!-- 2.4/2.6 kg for small/big battery pack -->
        <origin xyz="0 0 0"/>
        <inertia ixx="0.0001" ixy="0.0" ixz="0.0"
                 iyy="0.0001" iyz="0.0" 
                 izz="0.0001" />
      </inertial>
      <gazebo reference="base_link">
        <material>Gazebo/Black</material>
      </gazebo>
    </link>
    <joint name="wheel_left_joint" type="continuous">
      <parent link="base_link"/>
      <child link="wheel_left_link"/>
      <origin xyz="0.00 ${0.23/2} 0.0250" rpy="${-M_PI/2} 0 0"/>
      <axis xyz="0 0 1"/>
    </joint>
    <link name="wheel_left_link">
      <visual>
        <geometry>
          <mesh filename="package://kobuki_description/meshes/wheel.dae" scale="${M_SCALE} ${M_SCALE} ${M_SCALE}"/>
        </geometry>
        <origin xyz="0 0 0" rpy="0 ${M_PI/2} 0"/>
        <xacro:insert_block name="material_black"/>
      </visual>
      <collision>
        <geometry>
          <cylinder length="0.0206" radius="0.0352"/>
        </geometry>
        <origin rpy="0 0 0" xyz="0 0 0"/>
      </collision>      
      <inertial>
        <mass value="0.01" />
        <origin xyz="0 0 0" />        
        <inertia ixx="0.001" ixy="0.0" ixz="0.0"
                 iyy="0.001" iyz="0.0" 
                 izz="0.001" />
      </inertial>
    </link>
  
    <joint name="wheel_right_joint" type="continuous">
      <parent link="base_link"/>
      <child link="wheel_right_link"/>
      <origin xyz="0.00 -${0.23/2} 0.0250" rpy="${-M_PI/2} 0 0"/>
      <axis xyz="0 0 1"/>
    </joint>
    <link name="wheel_right_link">
      <visual>
        <geometry>
          <mesh filename="package://kobuki_description/meshes/wheel.dae" scale="${M_SCALE} ${M_SCALE} ${M_SCALE}"/>
        </geometry>
        <origin xyz="0 0 0" rpy="0 ${M_PI/2} 0"/>
        <xacro:insert_block name="material_black"/>
      </visual>
      <collision>
        <geometry>
          <cylinder length="0.0206" radius="0.0350"/>
        </geometry>
        <origin rpy="0 0 0" xyz="0 0 0"/>
      </collision>      
      <inertial>
        <mass value="0.01" />
        <origin xyz="0 0 0" />        
        <inertia ixx="0.001" ixy="0.0" ixz="0.0"
                 iyy="0.001" iyz="0.0" 
                 izz="0.001" />
      </inertial>
    </link>
  
    <!-- Kobuki's sensors -->
    <!-- TODO: Check placement! -->
    <joint name="gyro_joint" type="fixed">
      <axis xyz="0 1 0"/>
      <origin xyz="0 0 0.058" rpy="0 0 0"/>
      <parent link="base_link"/>
      <child link="gyro_link"/>
    </joint>
    <link name="gyro_link">
      <inertial>
        <mass value="0.001"/>
        <origin xyz="0 0 0" rpy="0 0 0"/>
        <inertia ixx="0.0001" ixy="0" ixz="0" 
                 iyy="0.000001" iyz="0"
                 izz="0.0001"/>
      </inertial>
    </link>
	
	  <joint name="cliff_sensor_left_joint" type="fixed">
	    <origin xyz="0.07 0.14 0.028" rpy="0 ${M_PI/2} 0" />        
	    <parent link="base_link"/>
	    <child link="cliff_sensor_left_link" />
	  </joint>
	  <link name="cliff_sensor_left_link">
      <inertial>
        <mass value="0.0001" />
        <origin xyz="0 0 0" />
        <inertia ixx="0.0001" ixy="0.0" ixz="0.0"
                 iyy="0.0001" iyz="0.0" 
                 izz="0.0001" />
      </inertial>
    </link>
	
	  <joint name="cliff_sensor_right_joint" type="fixed">
	    <origin xyz="0.07 -0.14 0.028" rpy="0 ${M_PI/2} 0" />        
	    <parent link="base_link"/>
	    <child link="cliff_sensor_right_link" />
	  </joint>
    <link name="cliff_sensor_right_link">
      <inertial>
        <mass value="0.0001" />
        <origin xyz="0 0 0" />
        <inertia ixx="0.0001" ixy="0.0" ixz="0.0"
                 iyy="0.0001" iyz="0.0" 
                 izz="0.0001" />
      </inertial>
    </link>
    
    <joint name="cliff_sensor_front_joint" type="fixed">
      <origin xyz="0.18 0.00 0.028" rpy="0 ${M_PI/2} 0" />        
      <parent link="base_link"/>
      <child link="cliff_sensor_front_link" />
    </joint>
    <link name="cliff_sensor_front_link">
      <inertial>
        <mass value="0.0001" />
        <origin xyz="0 0 0" />
        <inertia ixx="0.0001" ixy="0.0" ixz="0.0"
                 iyy="0.0001" iyz="0.0" 
                 izz="0.0001" />
      </inertial>
    </link>
   
    <!--  Gazebo additions -->
    <kobuki_sim/>
    <kobuki_cliff_sensors/>
    <turtlebot_sim_imu/>
  </xacro:macro>
</robot>